{
  "name": "oak_log_hut",
  "size": {
    "x": 5,
    "y": 3,
    "z": 5
  },
  "blocks": [
    {
      "x": 0,
      "y": 0,
      "z": 0,
      "name": "stone"
    },
    {
      "x": 1,
      "y": 0,
      "z": 0,
      "name": "stone"
    },
    {
      "x": 2,
      "y": 0,
      "z": 0,
      "name": "stone"
    },
    {
      "x": 3,
      "y": 0,
      "z": 0,
      "name": "stone"
    },
    {
      "x": 4,
      "y": 0,
      "z": 0,
      "name": "stone"
    },
    {
      "x": 0,
      "y": 0,
      "z": 1,
      "name": "stone"
    },
    {
      "x": 1,
      "y": 0,
      "z": 1,
      "name": "spruce_planks"
    },
    {
      "x": 2,
      "y": 0,
      "z": 1,
      "name": "oak_planks"
    },
    {
      "x": 3,
      "y": 0,
      "z": 1,
      "name": "oak_planks"
    },
    {
      "x": 4,
      "y": 0,
      "z": 1,
      "name": "glass_pane"
    },
    {
      "x": 0,
      "y": 0,
      "z": 2,
      "name": "stone"
    },
    {
      "x": 1,
      "y": 0,
      "z": 2,
      "name": "oak_planks"
    },
    {
      "x": 2,
      "y": 0,
      "z": 2,
      "name": "oak_planks"
    },
    {
      "x": 3,
      "y": 0,
      "z": 2,
      "name": "oak_planks"
    },
    {
      "x": 4,
      "y": 0,
      "z": 2,
      "name": "glass_pane"
    },
    {
      "x": 0,
      "y": 0,
      "z": 3,
      "name": "stone"
    },
    {
      "x": 1,
      "y": 0,
      "z": 3,
      "name": "oak_planks"
    },
    {
      "x": 2,
      "y": 0,
      "z": 3,
      "name": "oak_planks"
    },
    {
      "x": 3,
      "y": 0,
      "z": 3,
      "name": "oak_planks"
    },
    {
      "x": 4,
      "y": 0,
      "z": 3,
      "name": "glass_pane"
    },
    {
      "x": 0,
      "y": 0,
      "z": 4,
      "name": "stone"
    },
    {
      "x": 1,
      "y": 0,
      "z": 4,
      "name": "stone"
    },
    {
      "x": 2,
      "y": 0,
      "z": 4,
      "name": "stone"
    },
    {
      "x": 3,
      "y": 0,
      "z": 4,
      "name": "stone"
    },
    {
      "x": 4,
      "y": 0,
      "z": 4,
      "name": "stone"
    },
    {
      "x": 0,
      "y": 1,
      "z": 0,
      "name": "stone"
    },
    {
      "x": 1,
      "y": 1,
      "z": 0,
      "name": "stone"
    },
    {
      "x": 2,
      "y": 1,
      "z": 0,
      "name": "stone"
    },
    {
      "x": 3,
      "y": 1,
      "z": 0,
      "name": "stone"
    },
    {
      "x": 4,
      "y": 1,
      "z": 0,
      "name": "stone"
    },
    {
      "x": 0,
      "y": 1,
      "z": 1,
      "name": "stone"
    },
    {
      "x": 2,
      "y": 1,
      "z": 1,
      "name": "oak_planks"
    },
    {
      "x": 4,
      "y": 1,
      "z": 1,
      "name": "oak_planks"
    },
    {
      "x": 0,
      "y": 1,
      "z": 2,
      "name": "stone"
    },
    {
      "x": 2,
      "y": 1,
      "z": 2,
      "name": "oak_planks"
    },
    {
      "x": 4,
      "y": 1,
      "z": 2,
      "name": "oak_planks"
    },
    {
      "x": 0,
      "y": 1,
      "z": 3,
      "name": "stone"
    },
    {
      "x": 2,
      "y": 1,
      "z": 3,
      "name": "oak_planks"
    },
    {
      "x": 4,
      "y": 1,
      "z": 3,
      "name": "oak_planks"
    },
    {
      "x": 0,
      "y": 1,
      "z": 4,
      "name": "stone"
    },
    {
      "x": 1,
      "y": 1,
      "z": 4,
      "name": "stone"
    },
    {
      "x": 2,
      "y": 1,
      "z": 4,
      "name": "stone"
    },
    {
      "x": 3,
      "y": 1,
      "z": 4,
      "name": "stone"
    },
    {
      "x": 4,
      "y": 1,
      "z": 4,
      "name": "stone"
    },
    {
      "x": 0,
      "y": 2,
      "z": 0,
      "name": "stone"
    },
    {
      "x": 1,
      "y": 2,
      "z": 0,
      "name": "stone"
    },
    {
      "x": 2,
      "y": 2,
      "z": 0,
      "name": "stone"
    },
    {
      "x": 3,
      "y": 2,
      "z": 0,
      "name": "stone"
    },
    {
      "x": 4,
      "y": 2,
      "z": 0,
      "name": "stone"
    },
    {
      "x": 0,
      "y": 2,
      "z": 1,
      "name": "stone"
    },
    {
      "x": 1,
      "y": 2,
      "z": 1,
      "name": "oak_planks"
    },
    {
      "x": 2,
      "y": 2,
      "z": 1,
      "name": "oak_planks"
    },
    {
      "x": 3,
      "y": 2,
      "z": 1,
      "name": "oak_planks"
    },
    {
      "x": 4,
      "y": 2,
      "z": 1,
      "name": "glass_pane"
    },
    {
      "x": 0,
      "y": 2,
      "z": 2,
      "name": "stone"
    },
    {
      "x": 1,
      "y": 2,
      "z": 2,
      "name": "oak_planks"
    },
    {
      "x": 2,
      "y": 2,
      "z": 2,
      "name": "oak_planks"
    },
    {
      "x": 3,
      "y": 2,
      "z": 2,
      "name": "oak_planks"
    },
    {
      "x": 4,
      "y": 2,
      "z": 2,
      "name": "glass_pane"
    },
    {
      "x": 0,
      "y": 2,
      "z": 3,
      "name": "stone"
    },
    {
      "x": 1,
      "y": 2,
      "z": 3,
      "name": "oak_planks"
    },
    {
      "x": 2,
      "y": 2,
      "z": 3,
      "name": "oak_planks"
    },
    {
      "x": 3,
      "y": 2,
      "z": 3,
      "name": "oak_planks"
    },
    {
      "x": 4,
      "y": 2,
      "z": 3,
      "name": "glass_pane"
    },
    {
      "x": 0,
      "y": 2,
      "z": 4,
      "name": "stone"
    },
    {
      "x": 1,
      "y": 2,
      "z": 4,
      "name": "stone"
    },
    {
      "x": 2,
      "y": 2,
      "z": 4,
      "name": "stone"
    },
    {
      "x": 3,
      "y": 2,
      "z": 4,
      "name": "stone"
    },
    {
      "x": 4,
      "y": 2,
      "z": 4,
      "name": "stone"
    }
  ]
}