{
  "name": "cozy_cabin",
  "size": {
    "x": 7,
    "y": 5,
    "z": 7
  },
  "blocks": [
    {
      "x": 0,
      "y": 0,
      "z": 0,
      "name": "oak_planks",
      "props": {}
    },
    {
      "x": 0,
      "y": 0,
      "z": 1,
      "name": "oak_planks",
      "props": {}
    },
    {
      "x": 0,
      "y": 0,
      "z": 2,
      "name": "oak_planks",
      "props": {}
    },
    {
      "x": 0,
      "y": 0,
      "z": 3,
      "name": "oak_planks",
      "props": {}
    },
    {
      "x": 0,
      "y": 0,
      "z": 4,
      "name": "oak_planks",
      "props": {}
    },
    {
      "x": 0,
      "y": 0,
      "z": 5,
      "name": "oak_planks",
      "props": {}
    },
    {
      "x": 0,
      "y": 0,
      "z": 6,
      "name": "oak_planks",
      "props": {}
    },
    {
      "x": 1,
      "y": 0,
      "z": 0,
      "name": "oak_planks",
      "props": {}
    },
    {
      "x": 1,
      "y": 0,
      "z": 1,
      "name": "oak_planks",
      "props": {}
    },
    {
      "x": 1,
      "y": 0,
      "z": 2,
      "name": "oak_planks",
      "props": {}
    },
    {
      "x": 1,
      "y": 0,
      "z": 3,
      "name": "oak_planks",
      "props": {}
    },
    {
      "x": 1,
      "y": 0,
      "z": 4,
      "name": "oak_planks",
      "props": {}
    },
    {
      "x": 1,
      "y": 0,
      "z": 5,
      "name": "oak_planks",
      "props": {}
    },
    {
      "x": 1,
      "y": 0,
      "z": 6,
      "name": "oak_planks",
      "props": {}
    },
    {
      "x": 2,
      "y": 0,
      "z": 0,
      "name": "oak_planks",
      "props": {}
    },
    {
      "x": 2,
      "y": 0,
      "z": 1,
      "name": "oak_planks",
      "props": {}
    },
    {
      "x": 2,
      "y": 0,
      "z": 2,
      "name": "oak_planks",
      "props": {}
    },
    {
      "x": 2,
      "y": 0,
      "z": 3,
      "name": "oak_planks",
      "props": {}
    },
    {
      "x": 2,
      "y": 0,
      "z": 4,
      "name": "oak_planks",
      "props": {}
    },
    {
      "x": 2,
      "y": 0,
      "z": 5,
      "name": "oak_planks",
      "props": {}
    },
    {
      "x": 2,
      "y": 0,
      "z": 6,
      "name": "oak_planks",
      "props": {}
    },
    {
      "x": 3,
      "y": 0,
      "z": 0,
      "name": "oak_planks",
      "props": {}
    },
    {
      "x": 3,
      "y": 0,
      "z": 1,
      "name": "oak_planks",
      "props": {}
    },
    {
      "x": 3,
      "y": 0,
      "z": 2,
      "name": "oak_planks",
      "props": {}
    },
    {
      "x": 3,
      "y": 0,
      "z": 3,
      "name": "oak_planks",
      "props": {}
    },
    {
      "x": 3,
      "y": 0,
      "z": 4,
      "name": "oak_planks",
      "props": {}
    },
    {
      "x": 3,
      "y": 0,
      "z": 5,
      "name": "oak_planks",
      "props": {}
    },
    {
      "x": 3,
      "y": 0,
      "z": 6,
      "name": "oak_planks",
      "props": {}
    },
    {
      "x": 4,
      "y": 0,
      "z": 0,
      "name": "oak_planks",
      "props": {}
    },
    {
      "x": 4,
      "y": 0,
      "z": 1,
      "name": "oak_planks",
      "props": {}
    },
    {
      "x": 4,
      "y": 0,
      "z": 2,
      "name": "oak_planks",
      "props": {}
    },
    {
      "x": 4,
      "y": 0,
      "z": 3,
      "name": "oak_planks",
      "props": {}
    },
    {
      "x": 4,
      "y": 0,
      "z": 4,
      "name": "oak_planks",
      "props": {}
    },
    {
      "x": 4,
      "y": 0,
      "z": 5,
      "name": "oak_planks",
      "props": {}
    },
    {
      "x": 4,
      "y": 0,
      "z": 6,
      "name": "oak_planks",
      "props": {}
    },
    {
      "x": 5,
      "y": 0,
      "z": 0,
      "name": "oak_planks",
      "props": {}
    },
    {
      "x": 5,
      "y": 0,
      "z": 1,
      "name": "oak_planks",
      "props": {}
    },
    {
      "x": 5,
      "y": 0,
      "z": 2,
      "name": "oak_planks",
      "props": {}
    },
    {
      "x": 5,
      "y": 0,
      "z": 3,
      "name": "oak_planks",
      "props": {}
    },
    {
      "x": 5,
      "y": 0,
      "z": 4,
      "name": "oak_planks",
      "props": {}
    },
    {
      "x": 5,
      "y": 0,
      "z": 5,
      "name": "oak_planks",
      "props": {}
    },
    {
      "x": 5,
      "y": 0,
      "z": 6,
      "name": "oak_planks",
      "props": {}
    },
    {
      "x": 6,
      "y": 0,
      "z": 0,
      "name": "oak_planks",
      "props": {}
    },
    {
      "x": 6,
      "y": 0,
      "z": 1,
      "name": "oak_planks",
      "props": {}
    },
    {
      "x": 6,
      "y": 0,
      "z": 2,
      "name": "oak_planks",
      "props": {}
    },
    {
      "x": 6,
      "y": 0,
      "z": 3,
      "name": "oak_planks",
      "props": {}
    },
    {
      "x": 6,
      "y": 0,
      "z": 4,
      "name": "oak_planks",
      "props": {}
    },
    {
      "x": 6,
      "y": 0,
      "z": 5,
      "name": "oak_planks",
      "props": {}
    },
    {
      "x": 6,
      "y": 0,
      "z": 6,
      "name": "oak_planks",
      "props": {}
    },
    {
      "x": 0,
      "y": 1,
      "z": 0,
      "name": "spruce_planks",
      "props": {}
    },
    {
      "x": 0,
      "y": 1,
      "z": 1,
      "name": "spruce_planks",
      "props": {}
    },
    {
      "x": 0,
      "y": 1,
      "z": 2,
      "name": "spruce_planks",
      "props": {}
    },
    {
      "x": 0,
      "y": 1,
      "z": 3,
      "name": "spruce_planks",
      "props": {}
    },
    {
      "x": 0,
      "y": 1,
      "z": 4,
      "name": "spruce_planks",
      "props": {}
    },
    {
      "x": 0,
      "y": 1,
      "z": 5,
      "name": "spruce_planks",
      "props": {}
    },
    {
      "x": 0,
      "y": 1,
      "z": 6,
      "name": "spruce_planks",
      "props": {}
    },
    {
      "x": 1,
      "y": 1,
      "z": 0,
      "name": "spruce_planks",
      "props": {}
    },
    {
      "x": 1,
      "y": 1,
      "z": 6,
      "name": "spruce_planks",
      "props": {}
    },
    {
      "x": 2,
      "y": 1,
      "z": 0,
      "name": "spruce_planks",
      "props": {}
    },
    {
      "x": 2,
      "y": 1,
      "z": 6,
      "name": "spruce_planks",
      "props": {}
    },
    {
      "x": 3,
      "y": 1,
      "z": 0,
      "name": "spruce_planks",
      "props": {}
    },
    {
      "x": 4,
      "y": 1,
      "z": 0,
      "name": "spruce_planks",
      "props": {}
    },
    {
      "x": 4,
      "y": 1,
      "z": 6,
      "name": "spruce_planks",
      "props": {}
    },
    {
      "x": 5,
      "y": 1,
      "z": 0,
      "name": "spruce_planks",
      "props": {}
    },
    {
      "x": 5,
      "y": 1,
      "z": 6,
      "name": "spruce_planks",
      "props": {}
    },
    {
      "x": 6,
      "y": 1,
      "z": 0,
      "name": "spruce_planks",
      "props": {}
    },
    {
      "x": 6,
      "y": 1,
      "z": 1,
      "name": "spruce_planks",
      "props": {}
    },
    {
      "x": 6,
      "y": 1,
      "z": 2,
      "name": "spruce_planks",
      "props": {}
    },
    {
      "x": 6,
      "y": 1,
      "z": 3,
      "name": "spruce_planks",
      "props": {}
    },
    {
      "x": 6,
      "y": 1,
      "z": 4,
      "name": "spruce_planks",
      "props": {}
    },
    {
      "x": 6,
      "y": 1,
      "z": 5,
      "name": "spruce_planks",
      "props": {}
    },
    {
      "x": 6,
      "y": 1,
      "z": 6,
      "name": "spruce_planks",
      "props": {}
    },
    {
      "x": 0,
      "y": 2,
      "z": 0,
      "name": "spruce_planks",
      "props": {}
    },
    {
      "x": 0,
      "y": 2,
      "z": 1,
      "name": "spruce_planks",
      "props": {}
    },
    {
      "x": 0,
      "y": 2,
      "z": 2,
      "name": "spruce_planks",
      "props": {}
    },
    {
      "x": 0,
      "y": 2,
      "z": 3,
      "name": "spruce_planks",
      "props": {}
    },
    {
      "x": 0,
      "y": 2,
      "z": 4,
      "name": "spruce_planks",
      "props": {}
    },
    {
      "x": 0,
      "y": 2,
      "z": 5,
      "name": "spruce_planks",
      "props": {}
    },
    {
      "x": 0,
      "y": 2,
      "z": 6,
      "name": "spruce_planks",
      "props": {}
    },
    {
      "x": 1,
      "y": 2,
      "z": 0,
      "name": "spruce_planks",
      "props": {}
    },
    {
      "x": 1,
      "y": 2,
      "z": 6,
      "name": "spruce_planks",
      "props": {}
    },
    {
      "x": 2,
      "y": 2,
      "z": 6,
      "name": "spruce_planks",
      "props": {}
    },
    {
      "x": 3,
      "y": 2,
      "z": 0,
      "name": "spruce_planks",
      "props": {}
    },
    {
      "x": 4,
      "y": 2,
      "z": 6,
      "name": "spruce_planks",
      "props": {}
    },
    {
      "x": 5,
      "y": 2,
      "z": 0,
      "name": "spruce_planks",
      "props": {}
    },
    {
      "x": 5,
      "y": 2,
      "z": 6,
      "name": "spruce_planks",
      "props": {}
    },
    {
      "x": 6,
      "y": 2,
      "z": 0,
      "name": "spruce_planks",
      "props": {}
    },
    {
      "x": 6,
      "y": 2,
      "z": 1,
      "name": "spruce_planks",
      "props": {}
    },
    {
      "x": 6,
      "y": 2,
      "z": 2,
      "name": "spruce_planks",
      "props": {}
    },
    {
      "x": 6,
      "y": 2,
      "z": 3,
      "name": "spruce_planks",
      "props": {}
    },
    {
      "x": 6,
      "y": 2,
      "z": 4,
      "name": "spruce_planks",
      "props": {}
    },
    {
      "x": 6,
      "y": 2,
      "z": 5,
      "name": "spruce_planks",
      "props": {}
    },
    {
      "x": 6,
      "y": 2,
      "z": 6,
      "name": "spruce_planks",
      "props": {}
    },
    {
      "x": 0,
      "y": 3,
      "z": 0,
      "name": "spruce_planks",
      "props": {}
    },
    {
      "x": 0,
      "y": 3,
      "z": 1,
      "name": "spruce_planks",
      "props": {}
    },
    {
      "x": 0,
      "y": 3,
      "z": 2,
      "name": "spruce_planks",
      "props": {}
    },
    {
      "x": 0,
      "y": 3,
      "z": 3,
      "name": "spruce_planks",
      "props": {}
    },
    {
      "x": 0,
      "y": 3,
      "z": 4,
      "name": "spruce_planks",
      "props": {}
    },
    {
      "x": 0,
      "y": 3,
      "z": 5,
      "name": "spruce_planks",
      "props": {}
    },
    {
      "x": 0,
      "y": 3,
      "z": 6,
      "name": "spruce_planks",
      "props": {}
    },
    {
      "x": 1,
      "y": 3,
      "z": 0,
      "name": "spruce_planks",
      "props": {}
    },
    {
      "x": 1,
      "y": 3,
      "z": 6,
      "name": "spruce_planks",
      "props": {}
    },
    {
      "x": 2,
      "y": 3,
      "z": 0,
      "name": "spruce_planks",
      "props": {}
    },
    {
      "x": 2,
      "y": 3,
      "z": 6,
      "name": "spruce_planks",
      "props": {}
    },
    {
      "x": 3,
      "y": 3,
      "z": 0,
      "name": "spruce_planks",
      "props": {}
    },
    {
      "x": 3,
      "y": 3,
      "z": 6,
      "name": "spruce_planks",
      "props": {}
    },
    {
      "x": 4,
      "y": 3,
      "z": 0,
      "name": "spruce_planks",
      "props": {}
    },
    {
      "x": 4,
      "y": 3,
      "z": 6,
      "name": "spruce_planks",
      "props": {}
    },
    {
      "x": 5,
      "y": 3,
      "z": 0,
      "name": "spruce_planks",
      "props": {}
    },
    {
      "x": 5,
      "y": 3,
      "z": 6,
      "name": "spruce_planks",
      "props": {}
    },
    {
      "x": 6,
      "y": 3,
      "z": 0,
      "name": "spruce_planks",
      "props": {}
    },
    {
      "x": 6,
      "y": 3,
      "z": 1,
      "name": "spruce_planks",
      "props": {}
    },
    {
      "x": 6,
      "y": 3,
      "z": 2,
      "name": "spruce_planks",
      "props": {}
    },
    {
      "x": 6,
      "y": 3,
      "z": 3,
      "name": "spruce_planks",
      "props": {}
    },
    {
      "x": 6,
      "y": 3,
      "z": 4,
      "name": "spruce_planks",
      "props": {}
    },
    {
      "x": 6,
      "y": 3,
      "z": 5,
      "name": "spruce_planks",
      "props": {}
    },
    {
      "x": 6,
      "y": 3,
      "z": 6,
      "name": "spruce_planks",
      "props": {}
    },
    {
      "x": 0,
      "y": 4,
      "z": 0,
      "name": "oak_planks",
      "props": {}
    },
    {
      "x": 0,
      "y": 4,
      "z": 1,
      "name": "oak_planks",
      "props": {}
    },
    {
      "x": 0,
      "y": 4,
      "z": 2,
      "name": "oak_planks",
      "props": {}
    },
    {
      "x": 0,
      "y": 4,
      "z": 3,
      "name": "oak_planks",
      "props": {}
    },
    {
      "x": 0,
      "y": 4,
      "z": 4,
      "name": "oak_planks",
      "props": {}
    },
    {
      "x": 0,
      "y": 4,
      "z": 5,
      "name": "oak_planks",
      "props": {}
    },
    {
      "x": 0,
      "y": 4,
      "z": 6,
      "name": "oak_planks",
      "props": {}
    },
    {
      "x": 1,
      "y": 4,
      "z": 0,
      "name": "oak_planks",
      "props": {}
    },
    {
      "x": 1,
      "y": 4,
      "z": 1,
      "name": "oak_planks",
      "props": {}
    },
    {
      "x": 1,
      "y": 4,
      "z": 2,
      "name": "oak_planks",
      "props": {}
    },
    {
      "x": 1,
      "y": 4,
      "z": 3,
      "name": "oak_planks",
      "props": {}
    },
    {
      "x": 1,
      "y": 4,
      "z": 4,
      "name": "oak_planks",
      "props": {}
    },
    {
      "x": 1,
      "y": 4,
      "z": 5,
      "name": "oak_planks",
      "props": {}
    },
    {
      "x": 1,
      "y": 4,
      "z": 6,
      "name": "oak_planks",
      "props": {}
    },
    {
      "x": 2,
      "y": 4,
      "z": 0,
      "name": "oak_planks",
      "props": {}
    },
    {
      "x": 2,
      "y": 4,
      "z": 1,
      "name": "oak_planks",
      "props": {}
    },
    {
      "x": 2,
      "y": 4,
      "z": 2,
      "name": "oak_planks",
      "props": {}
    },
    {
      "x": 2,
      "y": 4,
      "z": 3,
      "name": "oak_planks",
      "props": {}
    },
    {
      "x": 2,
      "y": 4,
      "z": 4,
      "name": "oak_planks",
      "props": {}
    },
    {
      "x": 2,
      "y": 4,
      "z": 5,
      "name": "oak_planks",
      "props": {}
    },
    {
      "x": 2,
      "y": 4,
      "z": 6,
      "name": "oak_planks",
      "props": {}
    },
    {
      "x": 3,
      "y": 4,
      "z": 0,
      "name": "oak_planks",
      "props": {}
    },
    {
      "x": 3,
      "y": 4,
      "z": 1,
      "name": "oak_planks",
      "props": {}
    },
    {
      "x": 3,
      "y": 4,
      "z": 2,
      "name": "oak_planks",
      "props": {}
    },
    {
      "x": 3,
      "y": 4,
      "z": 3,
      "name": "oak_planks",
      "props": {}
    },
    {
      "x": 3,
      "y": 4,
      "z": 4,
      "name": "oak_planks",
      "props": {}
    },
    {
      "x": 3,
      "y": 4,
      "z": 5,
      "name": "oak_planks",
      "props": {}
    },
    {
      "x": 3,
      "y": 4,
      "z": 6,
      "name": "oak_planks",
      "props": {}
    },
    {
      "x": 4,
      "y": 4,
      "z": 0,
      "name": "oak_planks",
      "props": {}
    },
    {
      "x": 4,
      "y": 4,
      "z": 1,
      "name": "oak_planks",
      "props": {}
    },
    {
      "x": 4,
      "y": 4,
      "z": 2,
      "name": "oak_planks",
      "props": {}
    },
    {
      "x": 4,
      "y": 4,
      "z": 3,
      "name": "oak_planks",
      "props": {}
    },
    {
      "x": 4,
      "y": 4,
      "z": 4,
      "name": "oak_planks",
      "props": {}
    },
    {
      "x": 4,
      "y": 4,
      "z": 5,
      "name": "oak_planks",
      "props": {}
    },
    {
      "x": 4,
      "y": 4,
      "z": 6,
      "name": "oak_planks",
      "props": {}
    },
    {
      "x": 5,
      "y": 4,
      "z": 0,
      "name": "oak_planks",
      "props": {}
    },
    {
      "x": 5,
      "y": 4,
      "z": 1,
      "name": "oak_planks",
      "props": {}
    },
    {
      "x": 5,
      "y": 4,
      "z": 2,
      "name": "oak_planks",
      "props": {}
    },
    {
      "x": 5,
      "y": 4,
      "z": 3,
      "name": "oak_planks",
      "props": {}
    },
    {
      "x": 5,
      "y": 4,
      "z": 4,
      "name": "oak_planks",
      "props": {}
    },
    {
      "x": 5,
      "y": 4,
      "z": 5,
      "name": "oak_planks",
      "props": {}
    },
    {
      "x": 5,
      "y": 4,
      "z": 6,
      "name": "oak_planks",
      "props": {}
    },
    {
      "x": 6,
      "y": 4,
      "z": 0,
      "name": "oak_planks",
      "props": {}
    },
    {
      "x": 6,
      "y": 4,
      "z": 1,
      "name": "oak_planks",
      "props": {}
    },
    {
      "x": 6,
      "y": 4,
      "z": 2,
      "name": "oak_planks",
      "props": {}
    },
    {
      "x": 6,
      "y": 4,
      "z": 3,
      "name": "oak_planks",
      "props": {}
    },
    {
      "x": 6,
      "y": 4,
      "z": 4,
      "name": "oak_planks",
      "props": {}
    },
    {
      "x": 6,
      "y": 4,
      "z": 5,
      "name": "oak_planks",
      "props": {}
    },
    {
      "x": 6,
      "y": 4,
      "z": 6,
      "name": "oak_planks",
      "props": {}
    }
  ]
}