{
  "name": "cozy_treasure_tunnel",
  "size": {
    "x": 6,
    "y": 5,
    "z": 5
  },
  "blocks": [
    {
      "x": 0,
      "y": 0,
      "z": 0,
      "name": "stone"
    },
    {
      "x": 1,
      "y": 0,
      "z": 0,
      "name": "stone"
    },
    {
      "x": 2,
      "y": 0,
      "z": 0,
      "name": "stone"
    },
    {
      "x": 3,
      "y": 0,
      "z": 0,
      "name": "stone"
    },
    {
      "x": 4,
      "y": 0,
      "z": 0,
      "name": "stone"
    },
    {
      "x": 5,
      "y": 0,
      "z": 0,
      "name": "stone"
    },
    {
      "x": 0,
      "y": 0,
      "z": 1,
      "name": "stone"
    },
    {
      "x": 1,
      "y": 0,
      "z": 1,
      "name": "stone"
    },
    {
      "x": 2,
      "y": 0,
      "z": 1,
      "name": "stone"
    },
    {
      "x": 3,
      "y": 0,
      "z": 1,
      "name": "stone"
    },
    {
      "x": 4,
      "y": 0,
      "z": 1,
      "name": "stone"
    },
    {
      "x": 5,
      "y": 0,
      "z": 1,
      "name": "stone"
    },
    {
      "x": 0,
      "y": 0,
      "z": 2,
      "name": "stone"
    },
    {
      "x": 1,
      "y": 0,
      "z": 2,
      "name": "stone"
    },
    {
      "x": 2,
      "y": 0,
      "z": 2,
      "name": "stone"
    },
    {
      "x": 3,
      "y": 0,
      "z": 2,
      "name": "stone"
    },
    {
      "x": 4,
      "y": 0,
      "z": 2,
      "name": "stone"
    },
    {
      "x": 5,
      "y": 0,
      "z": 2,
      "name": "stone"
    },
    {
      "x": 0,
      "y": 0,
      "z": 3,
      "name": "stone"
    },
    {
      "x": 1,
      "y": 0,
      "z": 3,
      "name": "stone"
    },
    {
      "x": 2,
      "y": 0,
      "z": 3,
      "name": "stone"
    },
    {
      "x": 3,
      "y": 0,
      "z": 3,
      "name": "stone"
    },
    {
      "x": 4,
      "y": 0,
      "z": 3,
      "name": "stone"
    },
    {
      "x": 5,
      "y": 0,
      "z": 3,
      "name": "stone"
    },
    {
      "x": 0,
      "y": 0,
      "z": 4,
      "name": "stone"
    },
    {
      "x": 1,
      "y": 0,
      "z": 4,
      "name": "stone"
    },
    {
      "x": 2,
      "y": 0,
      "z": 4,
      "name": "stone"
    },
    {
      "x": 3,
      "y": 0,
      "z": 4,
      "name": "stone"
    },
    {
      "x": 4,
      "y": 0,
      "z": 4,
      "name": "stone"
    },
    {
      "x": 5,
      "y": 0,
      "z": 4,
      "name": "stone"
    },
    {
      "x": 0,
      "y": 1,
      "z": 0,
      "name": "stone"
    },
    {
      "x": 1,
      "y": 1,
      "z": 0,
      "name": "spruce_planks"
    },
    {
      "x": 2,
      "y": 1,
      "z": 0,
      "name": "oak_planks"
    },
    {
      "x": 3,
      "y": 1,
      "z": 0,
      "name": "oak_planks"
    },
    {
      "x": 4,
      "y": 1,
      "z": 0,
      "name": "oak_planks"
    },
    {
      "x": 5,
      "y": 1,
      "z": 0,
      "name": "stone"
    },
    {
      "x": 0,
      "y": 1,
      "z": 1,
      "name": "oak_planks"
    },
    {
      "x": 5,
      "y": 1,
      "z": 1,
      "name": "oak_planks"
    },
    {
      "x": 0,
      "y": 1,
      "z": 2,
      "name": "oak_planks"
    },
    {
      "x": 5,
      "y": 1,
      "z": 2,
      "name": "oak_planks"
    },
    {
      "x": 0,
      "y": 1,
      "z": 3,
      "name": "oak_planks"
    },
    {
      "x": 5,
      "y": 1,
      "z": 3,
      "name": "oak_planks"
    },
    {
      "x": 0,
      "y": 1,
      "z": 4,
      "name": "stone"
    },
    {
      "x": 1,
      "y": 1,
      "z": 4,
      "name": "oak_planks"
    },
    {
      "x": 2,
      "y": 1,
      "z": 4,
      "name": "oak_planks"
    },
    {
      "x": 3,
      "y": 1,
      "z": 4,
      "name": "oak_planks"
    },
    {
      "x": 4,
      "y": 1,
      "z": 4,
      "name": "oak_planks"
    },
    {
      "x": 5,
      "y": 1,
      "z": 4,
      "name": "stone"
    },
    {
      "x": 0,
      "y": 2,
      "z": 0,
      "name": "stone"
    },
    {
      "x": 1,
      "y": 2,
      "z": 0,
      "name": "oak_planks"
    },
    {
      "x": 2,
      "y": 2,
      "z": 0,
      "name": "oak_planks"
    },
    {
      "x": 3,
      "y": 2,
      "z": 0,
      "name": "oak_planks"
    },
    {
      "x": 4,
      "y": 2,
      "z": 0,
      "name": "oak_planks"
    },
    {
      "x": 5,
      "y": 2,
      "z": 0,
      "name": "stone"
    },
    {
      "x": 0,
      "y": 2,
      "z": 1,
      "name": "oak_planks"
    },
    {
      "x": 2,
      "y": 2,
      "z": 1,
      "name": "oak_planks"
    },
    {
      "x": 4,
      "y": 2,
      "z": 1,
      "name": "oak_planks"
    },
    {
      "x": 5,
      "y": 2,
      "z": 1,
      "name": "oak_planks"
    },
    {
      "x": 0,
      "y": 2,
      "z": 2,
      "name": "oak_planks"
    },
    {
      "x": 5,
      "y": 2,
      "z": 2,
      "name": "oak_planks"
    },
    {
      "x": 0,
      "y": 2,
      "z": 3,
      "name": "oak_planks"
    },
    {
      "x": 2,
      "y": 2,
      "z": 3,
      "name": "oak_planks"
    },
    {
      "x": 4,
      "y": 2,
      "z": 3,
      "name": "oak_planks"
    },
    {
      "x": 5,
      "y": 2,
      "z": 3,
      "name": "oak_planks"
    },
    {
      "x": 0,
      "y": 2,
      "z": 4,
      "name": "stone"
    },
    {
      "x": 1,
      "y": 2,
      "z": 4,
      "name": "oak_planks"
    },
    {
      "x": 2,
      "y": 2,
      "z": 4,
      "name": "oak_planks"
    },
    {
      "x": 3,
      "y": 2,
      "z": 4,
      "name": "oak_planks"
    },
    {
      "x": 4,
      "y": 2,
      "z": 4,
      "name": "oak_planks"
    },
    {
      "x": 5,
      "y": 2,
      "z": 4,
      "name": "stone"
    },
    {
      "x": 0,
      "y": 3,
      "z": 0,
      "name": "stone"
    },
    {
      "x": 1,
      "y": 3,
      "z": 0,
      "name": "oak_planks"
    },
    {
      "x": 2,
      "y": 3,
      "z": 0,
      "name": "oak_planks"
    },
    {
      "x": 3,
      "y": 3,
      "z": 0,
      "name": "oak_planks"
    },
    {
      "x": 4,
      "y": 3,
      "z": 0,
      "name": "oak_planks"
    },
    {
      "x": 5,
      "y": 3,
      "z": 0,
      "name": "stone"
    },
    {
      "x": 0,
      "y": 3,
      "z": 1,
      "name": "oak_planks"
    },
    {
      "x": 5,
      "y": 3,
      "z": 1,
      "name": "oak_planks"
    },
    {
      "x": 0,
      "y": 3,
      "z": 2,
      "name": "oak_planks"
    },
    {
      "x": 5,
      "y": 3,
      "z": 2,
      "name": "oak_planks"
    },
    {
      "x": 0,
      "y": 3,
      "z": 3,
      "name": "oak_planks"
    },
    {
      "x": 5,
      "y": 3,
      "z": 3,
      "name": "oak_planks"
    },
    {
      "x": 0,
      "y": 3,
      "z": 4,
      "name": "stone"
    },
    {
      "x": 1,
      "y": 3,
      "z": 4,
      "name": "oak_planks"
    },
    {
      "x": 2,
      "y": 3,
      "z": 4,
      "name": "oak_planks"
    },
    {
      "x": 3,
      "y": 3,
      "z": 4,
      "name": "oak_planks"
    },
    {
      "x": 4,
      "y": 3,
      "z": 4,
      "name": "oak_planks"
    },
    {
      "x": 5,
      "y": 3,
      "z": 4,
      "name": "stone"
    },
    {
      "x": 0,
      "y": 4,
      "z": 0,
      "name": "stone"
    },
    {
      "x": 1,
      "y": 4,
      "z": 0,
      "name": "stone"
    },
    {
      "x": 2,
      "y": 4,
      "z": 0,
      "name": "stone"
    },
    {
      "x": 3,
      "y": 4,
      "z": 0,
      "name": "stone"
    },
    {
      "x": 4,
      "y": 4,
      "z": 0,
      "name": "stone"
    },
    {
      "x": 5,
      "y": 4,
      "z": 0,
      "name": "stone"
    },
    {
      "x": 0,
      "y": 4,
      "z": 1,
      "name": "stone"
    },
    {
      "x": 1,
      "y": 4,
      "z": 1,
      "name": "stone"
    },
    {
      "x": 2,
      "y": 4,
      "z": 1,
      "name": "stone"
    },
    {
      "x": 3,
      "y": 4,
      "z": 1,
      "name": "stone"
    },
    {
      "x": 4,
      "y": 4,
      "z": 1,
      "name": "stone"
    },
    {
      "x": 5,
      "y": 4,
      "z": 1,
      "name": "stone"
    },
    {
      "x": 0,
      "y": 4,
      "z": 2,
      "name": "stone"
    },
    {
      "x": 1,
      "y": 4,
      "z": 2,
      "name": "stone"
    },
    {
      "x": 2,
      "y": 4,
      "z": 2,
      "name": "stone"
    },
    {
      "x": 3,
      "y": 4,
      "z": 2,
      "name": "stone"
    },
    {
      "x": 4,
      "y": 4,
      "z": 2,
      "name": "stone"
    },
    {
      "x": 5,
      "y": 4,
      "z": 2,
      "name": "stone"
    },
    {
      "x": 0,
      "y": 4,
      "z": 3,
      "name": "stone"
    },
    {
      "x": 1,
      "y": 4,
      "z": 3,
      "name": "stone"
    },
    {
      "x": 2,
      "y": 4,
      "z": 3,
      "name": "stone"
    },
    {
      "x": 3,
      "y": 4,
      "z": 3,
      "name": "stone"
    },
    {
      "x": 4,
      "y": 4,
      "z": 3,
      "name": "stone"
    },
    {
      "x": 5,
      "y": 4,
      "z": 3,
      "name": "stone"
    },
    {
      "x": 0,
      "y": 4,
      "z": 4,
      "name": "stone"
    },
    {
      "x": 1,
      "y": 4,
      "z": 4,
      "name": "stone"
    },
    {
      "x": 2,
      "y": 4,
      "z": 4,
      "name": "stone"
    },
    {
      "x": 3,
      "y": 4,
      "z": 4,
      "name": "stone"
    },
    {
      "x": 4,
      "y": 4,
      "z": 4,
      "name": "stone"
    },
    {
      "x": 5,
      "y": 4,
      "z": 4,
      "name": "stone"
    }
  ]
}