{
  "name": "quirky_dirt_statue_with_heart",
  "size": {
    "x": 4,
    "y": 4,
    "z": 5
  },
  "blocks": [
    {
      "x": 0,
      "y": 0,
      "z": 0,
      "name": "dirt"
    },
    {
      "x": 1,
      "y": 0,
      "z": 0,
      "name": "dirt"
    },
    {
      "x": 2,
      "y": 0,
      "z": 0,
      "name": "dirt"
    },
    {
      "x": 3,
      "y": 0,
      "z": 0,
      "name": "dirt"
    },
    {
      "x": 0,
      "y": 0,
      "z": 1,
      "name": "dirt"
    },
    {
      "x": 1,
      "y": 0,
      "z": 1,
      "name": "dirt"
    },
    {
      "x": 2,
      "y": 0,
      "z": 1,
      "name": "dirt"
    },
    {
      "x": 3,
      "y": 0,
      "z": 1,
      "name": "dirt"
    },
    {
      "x": 0,
      "y": 0,
      "z": 2,
      "name": "dirt"
    },
    {
      "x": 1,
      "y": 0,
      "z": 2,
      "name": "dirt"
    },
    {
      "x": 2,
      "y": 0,
      "z": 2,
      "name": "dirt"
    },
    {
      "x": 3,
      "y": 0,
      "z": 2,
      "name": "dirt"
    },
    {
      "x": 0,
      "y": 0,
      "z": 3,
      "name": "dirt"
    },
    {
      "x": 1,
      "y": 0,
      "z": 3,
      "name": "dirt"
    },
    {
      "x": 2,
      "y": 0,
      "z": 3,
      "name": "dirt"
    },
    {
      "x": 3,
      "y": 0,
      "z": 3,
      "name": "dirt"
    },
    {
      "x": 0,
      "y": 0,
      "z": 4,
      "name": "dirt"
    },
    {
      "x": 1,
      "y": 0,
      "z": 4,
      "name": "dirt"
    },
    {
      "x": 2,
      "y": 0,
      "z": 4,
      "name": "dirt"
    },
    {
      "x": 3,
      "y": 0,
      "z": 4,
      "name": "dirt"
    },
    {
      "x": 0,
      "y": 1,
      "z": 0,
      "name": "dirt"
    },
    {
      "x": 1,
      "y": 1,
      "z": 0,
      "name": "dirt"
    },
    {
      "x": 2,
      "y": 1,
      "z": 0,
      "name": "dirt"
    },
    {
      "x": 3,
      "y": 1,
      "z": 0,
      "name": "dirt"
    },
    {
      "x": 0,
      "y": 1,
      "z": 1,
      "name": "dirt"
    },
    {
      "x": 1,
      "y": 1,
      "z": 1,
      "name": "white_wool"
    },
    {
      "x": 2,
      "y": 1,
      "z": 1,
      "name": "white_wool"
    },
    {
      "x": 3,
      "y": 1,
      "z": 1,
      "name": "dirt"
    },
    {
      "x": 0,
      "y": 1,
      "z": 2,
      "name": "dirt"
    },
    {
      "x": 2,
      "y": 1,
      "z": 2,
      "name": "white_wool"
    },
    {
      "x": 3,
      "y": 1,
      "z": 2,
      "name": "dirt"
    },
    {
      "x": 0,
      "y": 1,
      "z": 3,
      "name": "dirt"
    },
    {
      "x": 1,
      "y": 1,
      "z": 3,
      "name": "white_wool"
    },
    {
      "x": 2,
      "y": 1,
      "z": 3,
      "name": "white_wool"
    },
    {
      "x": 3,
      "y": 1,
      "z": 3,
      "name": "dirt"
    },
    {
      "x": 0,
      "y": 1,
      "z": 4,
      "name": "dirt"
    },
    {
      "x": 1,
      "y": 1,
      "z": 4,
      "name": "dirt"
    },
    {
      "x": 2,
      "y": 1,
      "z": 4,
      "name": "dirt"
    },
    {
      "x": 3,
      "y": 1,
      "z": 4,
      "name": "dirt"
    },
    {
      "x": 0,
      "y": 2,
      "z": 0,
      "name": "dirt"
    },
    {
      "x": 1,
      "y": 2,
      "z": 0,
      "name": "dirt"
    },
    {
      "x": 2,
      "y": 2,
      "z": 0,
      "name": "dirt"
    },
    {
      "x": 3,
      "y": 2,
      "z": 0,
      "name": "dirt"
    },
    {
      "x": 0,
      "y": 2,
      "z": 1,
      "name": "dirt"
    },
    {
      "x": 1,
      "y": 2,
      "z": 1,
      "name": "white_wool"
    },
    {
      "x": 2,
      "y": 2,
      "z": 1,
      "name": "white_wool"
    },
    {
      "x": 3,
      "y": 2,
      "z": 1,
      "name": "dirt"
    },
    {
      "x": 0,
      "y": 2,
      "z": 2,
      "name": "dirt"
    },
    {
      "x": 1,
      "y": 2,
      "z": 2,
      "name": "white_wool"
    },
    {
      "x": 3,
      "y": 2,
      "z": 2,
      "name": "white_wool"
    },
    {
      "x": 0,
      "y": 2,
      "z": 3,
      "name": "dirt"
    },
    {
      "x": 1,
      "y": 2,
      "z": 3,
      "name": "white_wool"
    },
    {
      "x": 2,
      "y": 2,
      "z": 3,
      "name": "white_wool"
    },
    {
      "x": 3,
      "y": 2,
      "z": 3,
      "name": "dirt"
    },
    {
      "x": 0,
      "y": 2,
      "z": 4,
      "name": "dirt"
    },
    {
      "x": 1,
      "y": 2,
      "z": 4,
      "name": "dirt"
    },
    {
      "x": 2,
      "y": 2,
      "z": 4,
      "name": "dirt"
    },
    {
      "x": 3,
      "y": 2,
      "z": 4,
      "name": "dirt"
    },
    {
      "x": 0,
      "y": 3,
      "z": 0,
      "name": "dirt"
    },
    {
      "x": 1,
      "y": 3,
      "z": 0,
      "name": "dirt"
    },
    {
      "x": 2,
      "y": 3,
      "z": 0,
      "name": "dirt"
    },
    {
      "x": 3,
      "y": 3,
      "z": 0,
      "name": "dirt"
    },
    {
      "x": 0,
      "y": 3,
      "z": 1,
      "name": "dirt"
    },
    {
      "x": 1,
      "y": 3,
      "z": 1,
      "name": "dirt"
    },
    {
      "x": 2,
      "y": 3,
      "z": 1,
      "name": "dirt"
    },
    {
      "x": 3,
      "y": 3,
      "z": 1,
      "name": "dirt"
    },
    {
      "x": 0,
      "y": 3,
      "z": 2,
      "name": "dirt"
    },
    {
      "x": 1,
      "y": 3,
      "z": 2,
      "name": "dirt"
    },
    {
      "x": 2,
      "y": 3,
      "z": 2,
      "name": "dirt"
    },
    {
      "x": 3,
      "y": 3,
      "z": 2,
      "name": "dirt"
    },
    {
      "x": 0,
      "y": 3,
      "z": 3,
      "name": "dirt"
    },
    {
      "x": 1,
      "y": 3,
      "z": 3,
      "name": "dirt"
    },
    {
      "x": 2,
      "y": 3,
      "z": 3,
      "name": "dirt"
    },
    {
      "x": 3,
      "y": 3,
      "z": 3,
      "name": "dirt"
    },
    {
      "x": 0,
      "y": 3,
      "z": 4,
      "name": "dirt"
    },
    {
      "x": 1,
      "y": 3,
      "z": 4,
      "name": "dirt"
    },
    {
      "x": 2,
      "y": 3,
      "z": 4,
      "name": "dirt"
    },
    {
      "x": 3,
      "y": 3,
      "z": 4,
      "name": "dirt"
    }
  ]
}